[2023-10-31T17:42:49.127+0000] {taskinstance.py:1159} INFO - Dependencies all met for dep_context=non-requeueable deps ti=<TaskInstance: weather_report.email_weather manual__2023-10-31T17:41:38.394501+00:00 [queued]>
[2023-10-31T17:42:49.169+0000] {taskinstance.py:1159} INFO - Dependencies all met for dep_context=requeueable deps ti=<TaskInstance: weather_report.email_weather manual__2023-10-31T17:41:38.394501+00:00 [queued]>
[2023-10-31T17:42:49.170+0000] {taskinstance.py:1361} INFO - Starting attempt 2 of 2
[2023-10-31T17:42:49.242+0000] {taskinstance.py:1382} INFO - Executing <Task(PythonOperator): email_weather> on 2023-10-31 17:41:38.394501+00:00
[2023-10-31T17:42:49.264+0000] {standard_task_runner.py:57} INFO - Started process 252 to run task
[2023-10-31T17:42:49.273+0000] {standard_task_runner.py:84} INFO - Running: ['***', 'tasks', 'run', 'weather_report', 'email_weather', 'manual__2023-10-31T17:41:38.394501+00:00', '--job-id', '16', '--raw', '--subdir', 'DAGS_FOLDER/weather.py', '--cfg-path', '/tmp/tmp6u0prljy']
[2023-10-31T17:42:49.277+0000] {standard_task_runner.py:85} INFO - Job 16: Subtask email_weather
[2023-10-31T17:42:49.441+0000] {task_command.py:416} INFO - Running <TaskInstance: weather_report.email_weather manual__2023-10-31T17:41:38.394501+00:00 [running]> on host 583f39e4e8e0
[2023-10-31T17:42:49.721+0000] {taskinstance.py:1662} INFO - Exporting env vars: AIRFLOW_CTX_DAG_EMAIL='eriko.oy38@gmail.com' AIRFLOW_CTX_DAG_OWNER='***' AIRFLOW_CTX_DAG_ID='weather_report' AIRFLOW_CTX_TASK_ID='email_weather' AIRFLOW_CTX_EXECUTION_DATE='2023-10-31T17:41:38.394501+00:00' AIRFLOW_CTX_TRY_NUMBER='2' AIRFLOW_CTX_DAG_RUN_ID='manual__2023-10-31T17:41:38.394501+00:00'
[2023-10-31T17:42:49.762+0000] {logging_mixin.py:151} INFO - Emailing weather: {'condition': 'Partly cloudy', 'humidity': 86, 'temperature': -7.0}
[2023-10-31T17:42:50.473+0000] {taskinstance.py:1937} ERROR - Task failed with exception
Traceback (most recent call last):
  File "/home/airflow/.local/lib/python3.8/site-packages/airflow/operators/python.py", line 192, in execute
    return_value = self.execute_callable()
  File "/home/airflow/.local/lib/python3.8/site-packages/airflow/operators/python.py", line 209, in execute_callable
    return self.python_callable(*self.op_args, **self.op_kwargs)
  File "/opt/airflow/dags/weather.py", line 43, in email_weather
    s.login('eriko.oy38@gmail.com', '$MCz$gduo9f5#z')
  File "/usr/local/lib/python3.8/smtplib.py", line 748, in login
    raise last_exception
  File "/usr/local/lib/python3.8/smtplib.py", line 737, in login
    (code, resp) = self.auth(
  File "/usr/local/lib/python3.8/smtplib.py", line 660, in auth
    raise SMTPAuthenticationError(code, resp)
smtplib.SMTPAuthenticationError: (534, b'5.7.9 Application-specific password required. Learn more at\n5.7.9  https://support.google.com/mail/?p=InvalidSecondFactor dw9-20020a0565122c8900b0050085bb9e68sm268475lfb.101 - gsmtp')
[2023-10-31T17:42:50.483+0000] {taskinstance.py:1400} INFO - Marking task as FAILED. dag_id=weather_report, task_id=email_weather, execution_date=20231031T174138, start_date=20231031T174249, end_date=20231031T174250
[2023-10-31T17:42:50.500+0000] {standard_task_runner.py:104} ERROR - Failed to execute job 16 for task email_weather ((534, b'5.7.9 Application-specific password required. Learn more at\n5.7.9  https://support.google.com/mail/?p=InvalidSecondFactor dw9-20020a0565122c8900b0050085bb9e68sm268475lfb.101 - gsmtp'); 252)
[2023-10-31T17:42:50.527+0000] {local_task_job_runner.py:228} INFO - Task exited with return code 1
[2023-10-31T17:42:50.553+0000] {taskinstance.py:2778} INFO - 0 downstream tasks scheduled from follow-on schedule check
