[2023-10-31T17:53:54.899+0000] {taskinstance.py:1159} INFO - Dependencies all met for dep_context=non-requeueable deps ti=<TaskInstance: weather_report.email_weather manual__2023-10-31T17:52:46.521019+00:00 [queued]>
[2023-10-31T17:53:54.914+0000] {taskinstance.py:1159} INFO - Dependencies all met for dep_context=requeueable deps ti=<TaskInstance: weather_report.email_weather manual__2023-10-31T17:52:46.521019+00:00 [queued]>
[2023-10-31T17:53:54.915+0000] {taskinstance.py:1361} INFO - Starting attempt 2 of 2
[2023-10-31T17:53:54.940+0000] {taskinstance.py:1382} INFO - Executing <Task(PythonOperator): email_weather> on 2023-10-31 17:52:46.521019+00:00
[2023-10-31T17:53:54.949+0000] {standard_task_runner.py:57} INFO - Started process 437 to run task
[2023-10-31T17:53:54.953+0000] {standard_task_runner.py:84} INFO - Running: ['***', 'tasks', 'run', 'weather_report', 'email_weather', 'manual__2023-10-31T17:52:46.521019+00:00', '--job-id', '24', '--raw', '--subdir', 'DAGS_FOLDER/weather.py', '--cfg-path', '/tmp/tmpjo0lwfxr']
[2023-10-31T17:53:54.956+0000] {standard_task_runner.py:85} INFO - Job 24: Subtask email_weather
[2023-10-31T17:53:55.009+0000] {task_command.py:416} INFO - Running <TaskInstance: weather_report.email_weather manual__2023-10-31T17:52:46.521019+00:00 [running]> on host 583f39e4e8e0
[2023-10-31T17:53:55.108+0000] {taskinstance.py:1662} INFO - Exporting env vars: AIRFLOW_CTX_DAG_EMAIL='eriko.oy38@gmail.com' AIRFLOW_CTX_DAG_OWNER='***' AIRFLOW_CTX_DAG_ID='weather_report' AIRFLOW_CTX_TASK_ID='email_weather' AIRFLOW_CTX_EXECUTION_DATE='2023-10-31T17:52:46.521019+00:00' AIRFLOW_CTX_TRY_NUMBER='2' AIRFLOW_CTX_DAG_RUN_ID='manual__2023-10-31T17:52:46.521019+00:00'
[2023-10-31T17:53:55.121+0000] {logging_mixin.py:151} INFO - Emailing weather: {'condition': 'Partly cloudy', 'humidity': 86, 'temperature': -7.0}
[2023-10-31T17:53:55.123+0000] {taskinstance.py:1937} ERROR - Task failed with exception
Traceback (most recent call last):
  File "/home/airflow/.local/lib/python3.8/site-packages/airflow/operators/python.py", line 192, in execute
    return_value = self.execute_callable()
  File "/home/airflow/.local/lib/python3.8/site-packages/airflow/operators/python.py", line 209, in execute_callable
    return self.python_callable(*self.op_args, **self.op_kwargs)
  File "/opt/airflow/dags/weather.py", line 36, in email_weather
    email = os.environ['EMAIL']
  File "/usr/local/lib/python3.8/os.py", line 675, in __getitem__
    raise KeyError(key) from None
KeyError: 'EMAIL'
[2023-10-31T17:53:55.132+0000] {taskinstance.py:1400} INFO - Marking task as FAILED. dag_id=weather_report, task_id=email_weather, execution_date=20231031T175246, start_date=20231031T175354, end_date=20231031T175355
[2023-10-31T17:53:55.146+0000] {standard_task_runner.py:104} ERROR - Failed to execute job 24 for task email_weather ('EMAIL'; 437)
[2023-10-31T17:53:55.166+0000] {local_task_job_runner.py:228} INFO - Task exited with return code 1
[2023-10-31T17:53:55.186+0000] {taskinstance.py:2778} INFO - 0 downstream tasks scheduled from follow-on schedule check
