[2023-10-31T17:42:58.790+0000] {taskinstance.py:1159} INFO - Dependencies all met for dep_context=non-requeueable deps ti=<TaskInstance: weather_report.email_weather manual__2023-10-31T17:42:52.465827+00:00 [queued]>
[2023-10-31T17:42:58.803+0000] {taskinstance.py:1159} INFO - Dependencies all met for dep_context=requeueable deps ti=<TaskInstance: weather_report.email_weather manual__2023-10-31T17:42:52.465827+00:00 [queued]>
[2023-10-31T17:42:58.803+0000] {taskinstance.py:1361} INFO - Starting attempt 1 of 2
[2023-10-31T17:42:58.826+0000] {taskinstance.py:1382} INFO - Executing <Task(PythonOperator): email_weather> on 2023-10-31 17:42:52.465827+00:00
[2023-10-31T17:42:58.835+0000] {standard_task_runner.py:57} INFO - Started process 258 to run task
[2023-10-31T17:42:58.839+0000] {standard_task_runner.py:84} INFO - Running: ['***', 'tasks', 'run', 'weather_report', 'email_weather', 'manual__2023-10-31T17:42:52.465827+00:00', '--job-id', '18', '--raw', '--subdir', 'DAGS_FOLDER/weather.py', '--cfg-path', '/tmp/tmpkw59f81r']
[2023-10-31T17:42:58.842+0000] {standard_task_runner.py:85} INFO - Job 18: Subtask email_weather
[2023-10-31T17:42:58.893+0000] {task_command.py:416} INFO - Running <TaskInstance: weather_report.email_weather manual__2023-10-31T17:42:52.465827+00:00 [running]> on host 583f39e4e8e0
[2023-10-31T17:42:58.990+0000] {taskinstance.py:1662} INFO - Exporting env vars: AIRFLOW_CTX_DAG_EMAIL='eriko.oy38@gmail.com' AIRFLOW_CTX_DAG_OWNER='***' AIRFLOW_CTX_DAG_ID='weather_report' AIRFLOW_CTX_TASK_ID='email_weather' AIRFLOW_CTX_EXECUTION_DATE='2023-10-31T17:42:52.465827+00:00' AIRFLOW_CTX_TRY_NUMBER='1' AIRFLOW_CTX_DAG_RUN_ID='manual__2023-10-31T17:42:52.465827+00:00'
[2023-10-31T17:42:59.007+0000] {logging_mixin.py:151} INFO - Emailing weather: {'condition': 'Partly cloudy', 'humidity': 86, 'temperature': -7.0}
[2023-10-31T17:42:59.718+0000] {taskinstance.py:1937} ERROR - Task failed with exception
Traceback (most recent call last):
  File "/home/airflow/.local/lib/python3.8/site-packages/airflow/operators/python.py", line 192, in execute
    return_value = self.execute_callable()
  File "/home/airflow/.local/lib/python3.8/site-packages/airflow/operators/python.py", line 209, in execute_callable
    return self.python_callable(*self.op_args, **self.op_kwargs)
  File "/opt/airflow/dags/weather.py", line 43, in email_weather
    s.login('eriko.oy38@gmail.com', '$MCz$gduo9f5#z')
  File "/usr/local/lib/python3.8/smtplib.py", line 748, in login
    raise last_exception
  File "/usr/local/lib/python3.8/smtplib.py", line 737, in login
    (code, resp) = self.auth(
  File "/usr/local/lib/python3.8/smtplib.py", line 660, in auth
    raise SMTPAuthenticationError(code, resp)
smtplib.SMTPAuthenticationError: (534, b'5.7.9 Application-specific password required. Learn more at\n5.7.9  https://support.google.com/mail/?p=InvalidSecondFactor v28-20020a056512049c00b005032ebff220sm269543lfq.103 - gsmtp')
[2023-10-31T17:42:59.733+0000] {taskinstance.py:1400} INFO - Marking task as UP_FOR_RETRY. dag_id=weather_report, task_id=email_weather, execution_date=20231031T174252, start_date=20231031T174258, end_date=20231031T174259
[2023-10-31T17:42:59.755+0000] {standard_task_runner.py:104} ERROR - Failed to execute job 18 for task email_weather ((534, b'5.7.9 Application-specific password required. Learn more at\n5.7.9  https://support.google.com/mail/?p=InvalidSecondFactor v28-20020a056512049c00b005032ebff220sm269543lfq.103 - gsmtp'); 258)
[2023-10-31T17:42:59.774+0000] {local_task_job_runner.py:228} INFO - Task exited with return code 1
[2023-10-31T17:42:59.801+0000] {taskinstance.py:2778} INFO - 0 downstream tasks scheduled from follow-on schedule check
