[2023-10-31T17:33:41.455+0000] {taskinstance.py:1159} INFO - Dependencies all met for dep_context=non-requeueable deps ti=<TaskInstance: weather_report.email_weather manual__2023-10-31T17:33:25.647772+00:00 [queued]>
[2023-10-31T17:33:41.483+0000] {taskinstance.py:1159} INFO - Dependencies all met for dep_context=requeueable deps ti=<TaskInstance: weather_report.email_weather manual__2023-10-31T17:33:25.647772+00:00 [queued]>
[2023-10-31T17:33:41.484+0000] {taskinstance.py:1361} INFO - Starting attempt 1 of 2
[2023-10-31T17:33:41.533+0000] {taskinstance.py:1382} INFO - Executing <Task(PythonOperator): email_weather> on 2023-10-31 17:33:25.647772+00:00
[2023-10-31T17:33:41.549+0000] {standard_task_runner.py:57} INFO - Started process 83 to run task
[2023-10-31T17:33:41.554+0000] {standard_task_runner.py:84} INFO - Running: ['***', 'tasks', 'run', 'weather_report', 'email_weather', 'manual__2023-10-31T17:33:25.647772+00:00', '--job-id', '4', '--raw', '--subdir', 'DAGS_FOLDER/weather.py', '--cfg-path', '/tmp/tmpmtez1c_j']
[2023-10-31T17:33:41.568+0000] {standard_task_runner.py:85} INFO - Job 4: Subtask email_weather
[2023-10-31T17:33:41.679+0000] {task_command.py:416} INFO - Running <TaskInstance: weather_report.email_weather manual__2023-10-31T17:33:25.647772+00:00 [running]> on host 583f39e4e8e0
[2023-10-31T17:33:41.991+0000] {taskinstance.py:1662} INFO - Exporting env vars: AIRFLOW_CTX_DAG_EMAIL='eriko.oy38@gmail.com' AIRFLOW_CTX_DAG_OWNER='***' AIRFLOW_CTX_DAG_ID='weather_report' AIRFLOW_CTX_TASK_ID='email_weather' AIRFLOW_CTX_EXECUTION_DATE='2023-10-31T17:33:25.647772+00:00' AIRFLOW_CTX_TRY_NUMBER='1' AIRFLOW_CTX_DAG_RUN_ID='manual__2023-10-31T17:33:25.647772+00:00'
[2023-10-31T17:33:42.025+0000] {logging_mixin.py:151} INFO - Emailing weather: {'condition': 'Partly cloudy', 'humidity': 86, 'temperature': -7.0}
[2023-10-31T17:33:42.027+0000] {taskinstance.py:1937} ERROR - Task failed with exception
Traceback (most recent call last):
  File "/home/airflow/.local/lib/python3.8/site-packages/airflow/operators/python.py", line 192, in execute
    return_value = self.execute_callable()
  File "/home/airflow/.local/lib/python3.8/site-packages/airflow/operators/python.py", line 209, in execute_callable
    return self.python_callable(*self.op_args, **self.op_kwargs)
  File "/opt/airflow/dags/weather.py", line 42, in email_weather
    s = smtplib.SMTP('localhost')
  File "/usr/local/lib/python3.8/smtplib.py", line 255, in __init__
    (code, msg) = self.connect(host, port)
  File "/usr/local/lib/python3.8/smtplib.py", line 339, in connect
    self.sock = self._get_socket(host, port, self.timeout)
  File "/usr/local/lib/python3.8/smtplib.py", line 310, in _get_socket
    return socket.create_connection((host, port), timeout,
  File "/usr/local/lib/python3.8/socket.py", line 808, in create_connection
    raise err
  File "/usr/local/lib/python3.8/socket.py", line 796, in create_connection
    sock.connect(sa)
OSError: [Errno 99] Cannot assign requested address
[2023-10-31T17:33:42.047+0000] {taskinstance.py:1400} INFO - Marking task as UP_FOR_RETRY. dag_id=weather_report, task_id=email_weather, execution_date=20231031T173325, start_date=20231031T173341, end_date=20231031T173342
[2023-10-31T17:33:42.090+0000] {standard_task_runner.py:104} ERROR - Failed to execute job 4 for task email_weather ([Errno 99] Cannot assign requested address; 83)
[2023-10-31T17:33:42.151+0000] {local_task_job_runner.py:228} INFO - Task exited with return code 1
[2023-10-31T17:33:42.194+0000] {taskinstance.py:2778} INFO - 0 downstream tasks scheduled from follow-on schedule check
