[2023-10-31T17:04:37.356+0000] {taskinstance.py:1159} INFO - Dependencies all met for dep_context=non-requeueable deps ti=<TaskInstance: weather_report.fetch_weather manual__2023-10-31T17:04:35.042309+00:00 [queued]>
[2023-10-31T17:04:37.366+0000] {taskinstance.py:1159} INFO - Dependencies all met for dep_context=requeueable deps ti=<TaskInstance: weather_report.fetch_weather manual__2023-10-31T17:04:35.042309+00:00 [queued]>
[2023-10-31T17:04:37.367+0000] {taskinstance.py:1361} INFO - Starting attempt 1 of 2
[2023-10-31T17:04:37.383+0000] {taskinstance.py:1382} INFO - Executing <Task(PythonOperator): fetch_weather> on 2023-10-31 17:04:35.042309+00:00
[2023-10-31T17:04:37.390+0000] {standard_task_runner.py:57} INFO - Started process 814 to run task
[2023-10-31T17:04:37.394+0000] {standard_task_runner.py:84} INFO - Running: ['***', 'tasks', 'run', 'weather_report', 'fetch_weather', 'manual__2023-10-31T17:04:35.042309+00:00', '--job-id', '232', '--raw', '--subdir', 'DAGS_FOLDER/weather.py', '--cfg-path', '/tmp/tmp68mh_3xu']
[2023-10-31T17:04:37.397+0000] {standard_task_runner.py:85} INFO - Job 232: Subtask fetch_weather
[2023-10-31T17:04:37.459+0000] {task_command.py:416} INFO - Running <TaskInstance: weather_report.fetch_weather manual__2023-10-31T17:04:35.042309+00:00 [running]> on host 434ceb79d776
[2023-10-31T17:04:37.587+0000] {taskinstance.py:1662} INFO - Exporting env vars: AIRFLOW_CTX_DAG_EMAIL='eriko.oy38@gmail.com' AIRFLOW_CTX_DAG_OWNER='***' AIRFLOW_CTX_DAG_ID='weather_report' AIRFLOW_CTX_TASK_ID='fetch_weather' AIRFLOW_CTX_EXECUTION_DATE='2023-10-31T17:04:35.042309+00:00' AIRFLOW_CTX_TRY_NUMBER='1' AIRFLOW_CTX_DAG_RUN_ID='manual__2023-10-31T17:04:35.042309+00:00'
[2023-10-31T17:04:37.610+0000] {taskinstance.py:1937} ERROR - Task failed with exception
Traceback (most recent call last):
  File "/home/airflow/.local/lib/python3.8/site-packages/requests/models.py", line 971, in json
    return complexjson.loads(self.text, **kwargs)
  File "/usr/local/lib/python3.8/json/__init__.py", line 357, in loads
    return _default_decoder.decode(s)
  File "/usr/local/lib/python3.8/json/decoder.py", line 337, in decode
    obj, end = self.raw_decode(s, idx=_w(s, 0).end())
  File "/usr/local/lib/python3.8/json/decoder.py", line 355, in raw_decode
    raise JSONDecodeError("Expecting value", s, err.value) from None
json.decoder.JSONDecodeError: Expecting value: line 1 column 1 (char 0)

During handling of the above exception, another exception occurred:

Traceback (most recent call last):
  File "/home/airflow/.local/lib/python3.8/site-packages/airflow/operators/python.py", line 192, in execute
    return_value = self.execute_callable()
  File "/home/airflow/.local/lib/python3.8/site-packages/airflow/operators/python.py", line 209, in execute_callable
    return self.python_callable(*self.op_args, **self.op_kwargs)
  File "/opt/airflow/dags/weather.py", line 22, in fetch_weather
    return response.json()
  File "/home/airflow/.local/lib/python3.8/site-packages/requests/models.py", line 975, in json
    raise RequestsJSONDecodeError(e.msg, e.doc, e.pos)
requests.exceptions.JSONDecodeError: Expecting value: line 1 column 1 (char 0)
[2023-10-31T17:04:37.626+0000] {taskinstance.py:1400} INFO - Marking task as UP_FOR_RETRY. dag_id=weather_report, task_id=fetch_weather, execution_date=20231031T170435, start_date=20231031T170437, end_date=20231031T170437
[2023-10-31T17:04:37.643+0000] {standard_task_runner.py:104} ERROR - Failed to execute job 232 for task fetch_weather (Expecting value: line 1 column 1 (char 0); 814)
[2023-10-31T17:04:37.688+0000] {local_task_job_runner.py:228} INFO - Task exited with return code 1
[2023-10-31T17:04:37.719+0000] {taskinstance.py:2778} INFO - 0 downstream tasks scheduled from follow-on schedule check
