[2023-10-31T16:16:18.051+0000] {taskinstance.py:1159} INFO - Dependencies all met for dep_context=non-requeueable deps ti=<TaskInstance: flask_request.make_request manual__2023-10-31T16:16:15.338953+00:00 [queued]>
[2023-10-31T16:16:18.062+0000] {taskinstance.py:1159} INFO - Dependencies all met for dep_context=requeueable deps ti=<TaskInstance: flask_request.make_request manual__2023-10-31T16:16:15.338953+00:00 [queued]>
[2023-10-31T16:16:18.063+0000] {taskinstance.py:1361} INFO - Starting attempt 1 of 2
[2023-10-31T16:16:18.085+0000] {taskinstance.py:1382} INFO - Executing <Task(PythonOperator): make_request> on 2023-10-31 16:16:15.338953+00:00
[2023-10-31T16:16:18.094+0000] {standard_task_runner.py:57} INFO - Started process 77 to run task
[2023-10-31T16:16:18.098+0000] {standard_task_runner.py:84} INFO - Running: ['***', 'tasks', 'run', 'flask_request', 'make_request', 'manual__2023-10-31T16:16:15.338953+00:00', '--job-id', '221', '--raw', '--subdir', 'DAGS_FOLDER/test3.py', '--cfg-path', '/tmp/tmp9wk2s6xm']
[2023-10-31T16:16:18.101+0000] {standard_task_runner.py:85} INFO - Job 221: Subtask make_request
[2023-10-31T16:16:18.157+0000] {task_command.py:416} INFO - Running <TaskInstance: flask_request.make_request manual__2023-10-31T16:16:15.338953+00:00 [running]> on host 434ceb79d776
[2023-10-31T16:16:18.247+0000] {taskinstance.py:1662} INFO - Exporting env vars: AIRFLOW_CTX_DAG_EMAIL='your-email@example.com' AIRFLOW_CTX_DAG_OWNER='***' AIRFLOW_CTX_DAG_ID='flask_request' AIRFLOW_CTX_TASK_ID='make_request' AIRFLOW_CTX_EXECUTION_DATE='2023-10-31T16:16:15.338953+00:00' AIRFLOW_CTX_TRY_NUMBER='1' AIRFLOW_CTX_DAG_RUN_ID='manual__2023-10-31T16:16:15.338953+00:00'
[2023-10-31T16:16:18.253+0000] {taskinstance.py:1937} ERROR - Task failed with exception
Traceback (most recent call last):
  File "/home/airflow/.local/lib/python3.8/site-packages/urllib3/connection.py", line 174, in _new_conn
    conn = connection.create_connection(
  File "/home/airflow/.local/lib/python3.8/site-packages/urllib3/util/connection.py", line 95, in create_connection
    raise err
  File "/home/airflow/.local/lib/python3.8/site-packages/urllib3/util/connection.py", line 85, in create_connection
    sock.connect(sa)
ConnectionRefusedError: [Errno 111] Connection refused

During handling of the above exception, another exception occurred:

Traceback (most recent call last):
  File "/home/airflow/.local/lib/python3.8/site-packages/urllib3/connectionpool.py", line 714, in urlopen
    httplib_response = self._make_request(
  File "/home/airflow/.local/lib/python3.8/site-packages/urllib3/connectionpool.py", line 415, in _make_request
    conn.request(method, url, **httplib_request_kw)
  File "/home/airflow/.local/lib/python3.8/site-packages/urllib3/connection.py", line 244, in request
    super(HTTPConnection, self).request(method, url, body=body, headers=headers)
  File "/usr/local/lib/python3.8/http/client.py", line 1256, in request
    self._send_request(method, url, body, headers, encode_chunked)
  File "/usr/local/lib/python3.8/http/client.py", line 1302, in _send_request
    self.endheaders(body, encode_chunked=encode_chunked)
  File "/usr/local/lib/python3.8/http/client.py", line 1251, in endheaders
    self._send_output(message_body, encode_chunked=encode_chunked)
  File "/usr/local/lib/python3.8/http/client.py", line 1011, in _send_output
    self.send(msg)
  File "/usr/local/lib/python3.8/http/client.py", line 951, in send
    self.connect()
  File "/home/airflow/.local/lib/python3.8/site-packages/urllib3/connection.py", line 205, in connect
    conn = self._new_conn()
  File "/home/airflow/.local/lib/python3.8/site-packages/urllib3/connection.py", line 186, in _new_conn
    raise NewConnectionError(
urllib3.exceptions.NewConnectionError: <urllib3.connection.HTTPConnection object at 0x7fc3426f4430>: Failed to establish a new connection: [Errno 111] Connection refused

During handling of the above exception, another exception occurred:

Traceback (most recent call last):
  File "/home/airflow/.local/lib/python3.8/site-packages/requests/adapters.py", line 486, in send
    resp = conn.urlopen(
  File "/home/airflow/.local/lib/python3.8/site-packages/urllib3/connectionpool.py", line 798, in urlopen
    retries = retries.increment(
  File "/home/airflow/.local/lib/python3.8/site-packages/urllib3/util/retry.py", line 592, in increment
    raise MaxRetryError(_pool, url, error or ResponseError(cause))
urllib3.exceptions.MaxRetryError: HTTPConnectionPool(host='flask-app', port=5555): Max retries exceeded with url: /dag-test (Caused by NewConnectionError('<urllib3.connection.HTTPConnection object at 0x7fc3426f4430>: Failed to establish a new connection: [Errno 111] Connection refused'))

During handling of the above exception, another exception occurred:

Traceback (most recent call last):
  File "/home/airflow/.local/lib/python3.8/site-packages/airflow/operators/python.py", line 192, in execute
    return_value = self.execute_callable()
  File "/home/airflow/.local/lib/python3.8/site-packages/airflow/operators/python.py", line 209, in execute_callable
    return self.python_callable(*self.op_args, **self.op_kwargs)
  File "/opt/airflow/dags/test3.py", line 21, in make_request_to_flask
    response = requests.get('http://flask-app:5555/dag-test')
  File "/home/airflow/.local/lib/python3.8/site-packages/requests/api.py", line 73, in get
    return request("get", url, params=params, **kwargs)
  File "/home/airflow/.local/lib/python3.8/site-packages/requests/api.py", line 59, in request
    return session.request(method=method, url=url, **kwargs)
  File "/home/airflow/.local/lib/python3.8/site-packages/requests/sessions.py", line 589, in request
    resp = self.send(prep, **send_kwargs)
  File "/home/airflow/.local/lib/python3.8/site-packages/requests/sessions.py", line 703, in send
    r = adapter.send(request, **kwargs)
  File "/home/airflow/.local/lib/python3.8/site-packages/requests/adapters.py", line 519, in send
    raise ConnectionError(e, request=request)
requests.exceptions.ConnectionError: HTTPConnectionPool(host='flask-app', port=5555): Max retries exceeded with url: /dag-test (Caused by NewConnectionError('<urllib3.connection.HTTPConnection object at 0x7fc3426f4430>: Failed to establish a new connection: [Errno 111] Connection refused'))
[2023-10-31T16:16:18.266+0000] {taskinstance.py:1400} INFO - Marking task as UP_FOR_RETRY. dag_id=flask_request, task_id=make_request, execution_date=20231031T161615, start_date=20231031T161618, end_date=20231031T161618
[2023-10-31T16:16:18.281+0000] {standard_task_runner.py:104} ERROR - Failed to execute job 221 for task make_request (HTTPConnectionPool(host='flask-app', port=5555): Max retries exceeded with url: /dag-test (Caused by NewConnectionError('<urllib3.connection.HTTPConnection object at 0x7fc3426f4430>: Failed to establish a new connection: [Errno 111] Connection refused')); 77)
[2023-10-31T16:16:18.311+0000] {local_task_job_runner.py:228} INFO - Task exited with return code 1
[2023-10-31T16:16:18.341+0000] {taskinstance.py:2778} INFO - 0 downstream tasks scheduled from follow-on schedule check
