[2023-10-31T17:40:53.783+0000] {taskinstance.py:1159} INFO - Dependencies all met for dep_context=non-requeueable deps ti=<TaskInstance: weather_report.email_weather manual__2023-10-31T17:38:50.351020+00:00 [queued]>
[2023-10-31T17:40:53.795+0000] {taskinstance.py:1159} INFO - Dependencies all met for dep_context=requeueable deps ti=<TaskInstance: weather_report.email_weather manual__2023-10-31T17:38:50.351020+00:00 [queued]>
[2023-10-31T17:40:53.796+0000] {taskinstance.py:1361} INFO - Starting attempt 2 of 2
[2023-10-31T17:40:53.825+0000] {taskinstance.py:1382} INFO - Executing <Task(PythonOperator): email_weather> on 2023-10-31 17:38:50.351020+00:00
[2023-10-31T17:40:53.833+0000] {standard_task_runner.py:57} INFO - Started process 207 to run task
[2023-10-31T17:40:53.837+0000] {standard_task_runner.py:84} INFO - Running: ['***', 'tasks', 'run', 'weather_report', 'email_weather', 'manual__2023-10-31T17:38:50.351020+00:00', '--job-id', '12', '--raw', '--subdir', 'DAGS_FOLDER/weather.py', '--cfg-path', '/tmp/tmpb_z8nnda']
[2023-10-31T17:40:53.840+0000] {standard_task_runner.py:85} INFO - Job 12: Subtask email_weather
[2023-10-31T17:40:53.890+0000] {task_command.py:416} INFO - Running <TaskInstance: weather_report.email_weather manual__2023-10-31T17:38:50.351020+00:00 [running]> on host 583f39e4e8e0
[2023-10-31T17:40:54.022+0000] {taskinstance.py:1662} INFO - Exporting env vars: AIRFLOW_CTX_DAG_EMAIL='eriko.oy38@gmail.com' AIRFLOW_CTX_DAG_OWNER='***' AIRFLOW_CTX_DAG_ID='weather_report' AIRFLOW_CTX_TASK_ID='email_weather' AIRFLOW_CTX_EXECUTION_DATE='2023-10-31T17:38:50.351020+00:00' AIRFLOW_CTX_TRY_NUMBER='2' AIRFLOW_CTX_DAG_RUN_ID='manual__2023-10-31T17:38:50.351020+00:00'
[2023-10-31T17:40:54.038+0000] {logging_mixin.py:151} INFO - Emailing weather: {'condition': 'Partly cloudy', 'humidity': 86, 'temperature': -7.0}
[2023-10-31T17:40:54.801+0000] {taskinstance.py:1937} ERROR - Task failed with exception
Traceback (most recent call last):
  File "/home/airflow/.local/lib/python3.8/site-packages/airflow/operators/python.py", line 192, in execute
    return_value = self.execute_callable()
  File "/home/airflow/.local/lib/python3.8/site-packages/airflow/operators/python.py", line 209, in execute_callable
    return self.python_callable(*self.op_args, **self.op_kwargs)
  File "/opt/airflow/dags/weather.py", line 43, in email_weather
    s.login('eriko.oy38@gmail.com', 'a)(HG/=&TGFV')
  File "/usr/local/lib/python3.8/smtplib.py", line 748, in login
    raise last_exception
  File "/usr/local/lib/python3.8/smtplib.py", line 737, in login
    (code, resp) = self.auth(
  File "/usr/local/lib/python3.8/smtplib.py", line 660, in auth
    raise SMTPAuthenticationError(code, resp)
smtplib.SMTPAuthenticationError: (535, b'5.7.8 Username and Password not accepted. Learn more at\n5.7.8  https://support.google.com/mail/?p=BadCredentials u24-20020a196a18000000b005031641b40asm265954lfu.159 - gsmtp')
[2023-10-31T17:40:54.814+0000] {taskinstance.py:1400} INFO - Marking task as FAILED. dag_id=weather_report, task_id=email_weather, execution_date=20231031T173850, start_date=20231031T174053, end_date=20231031T174054
[2023-10-31T17:40:54.852+0000] {standard_task_runner.py:104} ERROR - Failed to execute job 12 for task email_weather ((535, b'5.7.8 Username and Password not accepted. Learn more at\n5.7.8  https://support.google.com/mail/?p=BadCredentials u24-20020a196a18000000b005031641b40asm265954lfu.159 - gsmtp'); 207)
[2023-10-31T17:40:54.894+0000] {local_task_job_runner.py:228} INFO - Task exited with return code 1
[2023-10-31T17:40:54.922+0000] {taskinstance.py:2778} INFO - 0 downstream tasks scheduled from follow-on schedule check
