[2023-10-31T15:00:30.809+0000] {taskinstance.py:1159} INFO - Dependencies all met for dep_context=non-requeueable deps ti=<TaskInstance: 1_TEST-predict_value_dag.predict_value_task scheduled__2023-05-13T00:00:00+00:00 [queued]>
[2023-10-31T15:00:30.821+0000] {taskinstance.py:1159} INFO - Dependencies all met for dep_context=requeueable deps ti=<TaskInstance: 1_TEST-predict_value_dag.predict_value_task scheduled__2023-05-13T00:00:00+00:00 [queued]>
[2023-10-31T15:00:30.822+0000] {taskinstance.py:1361} INFO - Starting attempt 1 of 2
[2023-10-31T15:00:30.858+0000] {taskinstance.py:1382} INFO - Executing <Task(PythonOperator): predict_value_task> on 2023-05-13 00:00:00+00:00
[2023-10-31T15:00:30.871+0000] {standard_task_runner.py:57} INFO - Started process 282 to run task
[2023-10-31T15:00:30.873+0000] {standard_task_runner.py:84} INFO - Running: ['***', 'tasks', 'run', '1_TEST-predict_value_dag', 'predict_value_task', 'scheduled__2023-05-13T00:00:00+00:00', '--job-id', '72', '--raw', '--subdir', 'DAGS_FOLDER/test.py', '--cfg-path', '/tmp/tmp_weczm_2']
[2023-10-31T15:00:30.895+0000] {standard_task_runner.py:85} INFO - Job 72: Subtask predict_value_task
[2023-10-31T15:00:31.058+0000] {task_command.py:416} INFO - Running <TaskInstance: 1_TEST-predict_value_dag.predict_value_task scheduled__2023-05-13T00:00:00+00:00 [running]> on host 091dc6acb41b
[2023-10-31T15:00:31.221+0000] {taskinstance.py:1662} INFO - Exporting env vars: AIRFLOW_CTX_DAG_OWNER='***' AIRFLOW_CTX_DAG_ID='1_TEST-predict_value_dag' AIRFLOW_CTX_TASK_ID='predict_value_task' AIRFLOW_CTX_EXECUTION_DATE='2023-05-13T00:00:00+00:00' AIRFLOW_CTX_TRY_NUMBER='1' AIRFLOW_CTX_DAG_RUN_ID='scheduled__2023-05-13T00:00:00+00:00'
[2023-10-31T15:00:39.243+0000] {taskinstance.py:1937} ERROR - Task failed with exception
Traceback (most recent call last):
  File "/home/airflow/.local/lib/python3.8/site-packages/urllib3/connection.py", line 174, in _new_conn
    conn = connection.create_connection(
  File "/home/airflow/.local/lib/python3.8/site-packages/urllib3/util/connection.py", line 72, in create_connection
    for res in socket.getaddrinfo(host, port, family, socket.SOCK_STREAM):
  File "/usr/local/lib/python3.8/socket.py", line 918, in getaddrinfo
    for res in _socket.getaddrinfo(host, port, family, type, proto, flags):
socket.gaierror: [Errno -3] Temporary failure in name resolution

During handling of the above exception, another exception occurred:

Traceback (most recent call last):
  File "/home/airflow/.local/lib/python3.8/site-packages/urllib3/connectionpool.py", line 714, in urlopen
    httplib_response = self._make_request(
  File "/home/airflow/.local/lib/python3.8/site-packages/urllib3/connectionpool.py", line 415, in _make_request
    conn.request(method, url, **httplib_request_kw)
  File "/home/airflow/.local/lib/python3.8/site-packages/urllib3/connection.py", line 244, in request
    super(HTTPConnection, self).request(method, url, body=body, headers=headers)
  File "/usr/local/lib/python3.8/http/client.py", line 1256, in request
    self._send_request(method, url, body, headers, encode_chunked)
  File "/usr/local/lib/python3.8/http/client.py", line 1302, in _send_request
    self.endheaders(body, encode_chunked=encode_chunked)
  File "/usr/local/lib/python3.8/http/client.py", line 1251, in endheaders
    self._send_output(message_body, encode_chunked=encode_chunked)
  File "/usr/local/lib/python3.8/http/client.py", line 1011, in _send_output
    self.send(msg)
  File "/usr/local/lib/python3.8/http/client.py", line 951, in send
    self.connect()
  File "/home/airflow/.local/lib/python3.8/site-packages/urllib3/connection.py", line 205, in connect
    conn = self._new_conn()
  File "/home/airflow/.local/lib/python3.8/site-packages/urllib3/connection.py", line 186, in _new_conn
    raise NewConnectionError(
urllib3.exceptions.NewConnectionError: <urllib3.connection.HTTPConnection object at 0x7f0af7e16940>: Failed to establish a new connection: [Errno -3] Temporary failure in name resolution

During handling of the above exception, another exception occurred:

Traceback (most recent call last):
  File "/home/airflow/.local/lib/python3.8/site-packages/requests/adapters.py", line 486, in send
    resp = conn.urlopen(
  File "/home/airflow/.local/lib/python3.8/site-packages/urllib3/connectionpool.py", line 798, in urlopen
    retries = retries.increment(
  File "/home/airflow/.local/lib/python3.8/site-packages/urllib3/util/retry.py", line 592, in increment
    raise MaxRetryError(_pool, url, error or ResponseError(cause))
urllib3.exceptions.MaxRetryError: HTTPConnectionPool(host='flask-app', port=5555): Max retries exceeded with url: /predict (Caused by NewConnectionError('<urllib3.connection.HTTPConnection object at 0x7f0af7e16940>: Failed to establish a new connection: [Errno -3] Temporary failure in name resolution'))

During handling of the above exception, another exception occurred:

Traceback (most recent call last):
  File "/home/airflow/.local/lib/python3.8/site-packages/airflow/operators/python.py", line 192, in execute
    return_value = self.execute_callable()
  File "/home/airflow/.local/lib/python3.8/site-packages/airflow/operators/python.py", line 209, in execute_callable
    return self.python_callable(*self.op_args, **self.op_kwargs)
  File "/opt/airflow/dags/test.py", line 10, in predict_value
    response = requests.post(url, json=data)
  File "/home/airflow/.local/lib/python3.8/site-packages/requests/api.py", line 115, in post
    return request("post", url, data=data, json=json, **kwargs)
  File "/home/airflow/.local/lib/python3.8/site-packages/requests/api.py", line 59, in request
    return session.request(method=method, url=url, **kwargs)
  File "/home/airflow/.local/lib/python3.8/site-packages/requests/sessions.py", line 589, in request
    resp = self.send(prep, **send_kwargs)
  File "/home/airflow/.local/lib/python3.8/site-packages/requests/sessions.py", line 703, in send
    r = adapter.send(request, **kwargs)
  File "/home/airflow/.local/lib/python3.8/site-packages/requests/adapters.py", line 519, in send
    raise ConnectionError(e, request=request)
requests.exceptions.ConnectionError: HTTPConnectionPool(host='flask-app', port=5555): Max retries exceeded with url: /predict (Caused by NewConnectionError('<urllib3.connection.HTTPConnection object at 0x7f0af7e16940>: Failed to establish a new connection: [Errno -3] Temporary failure in name resolution'))
[2023-10-31T15:00:39.258+0000] {taskinstance.py:1400} INFO - Marking task as UP_FOR_RETRY. dag_id=1_TEST-predict_value_dag, task_id=predict_value_task, execution_date=20230513T000000, start_date=20231031T150030, end_date=20231031T150039
[2023-10-31T15:00:39.390+0000] {standard_task_runner.py:104} ERROR - Failed to execute job 72 for task predict_value_task (HTTPConnectionPool(host='flask-app', port=5555): Max retries exceeded with url: /predict (Caused by NewConnectionError('<urllib3.connection.HTTPConnection object at 0x7f0af7e16940>: Failed to establish a new connection: [Errno -3] Temporary failure in name resolution')); 282)
[2023-10-31T15:00:39.422+0000] {local_task_job_runner.py:228} INFO - Task exited with return code 1
[2023-10-31T15:00:39.444+0000] {taskinstance.py:2778} INFO - 0 downstream tasks scheduled from follow-on schedule check
